2025-05-24 18:39:13,905 - llm_entropy.analysis - INFO - Starting analysis run 20250524_183913_d23a4662
2025-05-24 18:39:13,905 - llm_entropy.analysis - INFO - Loading models...
2025-05-24 18:39:14,858 - llm_entropy.analysis - INFO - Generating example sentences...
2025-05-24 18:42:54,926 - llm_entropy.analysis - ERROR - Analysis failed: 'int' object is not callable
Traceback (most recent call last):
  File "/Users/finchmf/coding/entropy/llm_entropy/main.py", line 137, in run_analysis
    bert_results.extend(future.result())
  File "/Library/Frameworks/Python.framework/Versions/3.10/lib/python3.10/concurrent/futures/_base.py", line 438, in result
    return self.__get_result()
  File "/Library/Frameworks/Python.framework/Versions/3.10/lib/python3.10/concurrent/futures/_base.py", line 390, in __get_result
    raise self._exception
  File "/Library/Frameworks/Python.framework/Versions/3.10/lib/python3.10/concurrent/futures/thread.py", line 52, in run
    result = self.fn(*self.args, **self.kwargs)
  File "/Users/finchmf/coding/entropy/llm_entropy/main.py", line 64, in process_batch
    result = analysis_func(sent, model, tokenizer, mask_index, **kwargs)
  File "/Users/finchmf/coding/entropy/llm_entropy/analysis.py", line 158, in bert_entropy_analysis
    inputs = tokenizer(text, return_tensors="pt")
TypeError: 'int' object is not callable
